Workbook

Sheet Übersicht
A1: Kfz-Aktion Fahrschulen – Pforzheim & Enzkreis
A2: Stand Recherche: 26.10.2026 – alle Werte rechnen automatisch aus dem Blatt „Fahrschulen“.
A4: Status | B4: Pforzheim | C4: Enzkreis | D4: Gesamt | F4: Provision pro Empfehlung (€) | G4: 60
A5: Offen | B5: =COUNTIFS(Fahrschulen!$C$2:$C$45,"Pforzheim",Fahrschulen!$L$2:$L$45,"Offen") -> 16 | C5: =COUNTIFS(Fahrschulen!$C$2:$C$45,"Enzkreis",Fahrschulen!$L$2:$L$45,"Offen") -> 28 | D5: =B5+C5 -> 44 | F5: (gelbe Zelle änderbar)
A6: Angeschrieben | B6: =COUNTIFS(Fahrschulen!$C$2:$C$45,"Pforzheim",Fahrschulen!$L$2:$L$45,"Angeschrieben") -> 0 | C6: =COUNTIFS(Fahrschulen!$C$2:$C$45,"Enzkreis",Fahrschulen!$L$2:$L$45,"Angeschrieben") -> 0 | D6: =B6+C6 -> 0
A7: Angerufen | B7: =COUNTIFS(Fahrschulen!$C$2:$C$45,"Pforzheim",Fahrschulen!$L$2:$L$45,"Angerufen") -> 0 | C7: =COUNTIFS(Fahrschulen!$C$2:$C$45,"Enzkreis",Fahrschulen!$L$2:$L$45,"Angerufen") -> 0 | D7: =B7+C7 -> 0 | F7: Interesse Fahrschulflotte (Marvin) | G7: =COUNTIF(Fahrschulen!$V$2:$V$45,"Ja")+COUNTIF(Fahrschulen!$V$2:$V$45,"An Marvin übergeben") -> 0
A8: Nachfassen | B8: =COUNTIFS(Fahrschulen!$C$2:$C$45,"Pforzheim",Fahrschulen!$L$2:$L$45,"Nachfassen") -> 0 | C8: =COUNTIFS(Fahrschulen!$C$2:$C$45,"Enzkreis",Fahrschulen!$L$2:$L$45,"Nachfassen") -> 0 | D8: =B8+C8 -> 0
A9: Termin vereinbart | B9: =COUNTIFS(Fahrschulen!$C$2:$C$45,"Pforzheim",Fahrschulen!$L$2:$L$45,"Termin vereinbart") -> 0 | C9: =COUNTIFS(Fahrschulen!$C$2:$C$45,"Enzkreis",Fahrschulen!$L$2:$L$45,"Termin vereinbart") -> 0 | D9: =B9+C9 -> 0
A10: Vortrag gehalten | B10: =COUNTIFS(Fahrschulen!$C$2:$C$45,"Pforzheim",Fahrschulen!$L$2:$L$45,"Vortrag gehalten") -> 0 | C10: =COUNTIFS(Fahrschulen!$C$2:$C$45,"Enzkreis",Fahrschulen!$L$2:$L$45,"Vortrag gehalten") -> 0 | D10: =B10+C10 -> 0
A11: Kooperation aktiv | B11: =COUNTIFS(Fahrschulen!$C$2:$C$45,"Pforzheim",Fahrschulen!$L$2:$L$45,"Kooperation aktiv") -> 0 | C11: =COUNTIFS(Fahrschulen!$C$2:$C$45,"Enzkreis",Fahrschulen!$L$2:$L$45,"Kooperation aktiv") -> 0 | D11: =B11+C11 -> 0
A12: Kein Interesse | B12: =COUNTIFS(Fahrschulen!$C$2:$C$45,"Pforzheim",Fahrschulen!$L$2:$L$45,"Kein Interesse") -> 0 | C12: =COUNTIFS(Fahrschulen!$C$2:$C$45,"Enzkreis",Fahrschulen!$L$2:$L$45,"Kein Interesse") -> 0 | D12: =B12+C12 -> 0
A13: Geschlossen / existiert nicht | B13: =COUNTIFS(Fahrschulen!$C$2:$C$45,"Pforzheim",Fahrschulen!$L$2:$L$45,"Geschlossen / existiert nicht") -> 0 | C13: =COUNTIFS(Fahrschulen!$C$2:$C$45,"Enzkreis",Fahrschulen!$L$2:$L$45,"Geschlossen / existiert nicht") -> 0 | D13: =B13+C13 -> 0
A14: Fahrschulen gesamt | B14: =SUM(B5:B13) -> 16 | C14: =SUM(C5:C13) -> 28 | D14: =SUM(D5:D13) -> 44
A16: Kennzahlen | B16: Pforzheim | C16: Enzkreis | D16: Gesamt
A17: Daten geprüft | B17: =COUNTIFS(Fahrschulen!$C$2:$C$45,"Pforzheim",Fahrschulen!$K$2:$K$45,"Ja") -> 0 | C17: =COUNTIFS(Fahrschulen!$C$2:$C$45,"Enzkreis",Fahrschulen!$K$2:$K$45,"Ja") -> 0 | D17: =B17+C17 -> 0
A18: Tippgeber-Vereinbarung unterschrieben | B18: =COUNTIFS(Fahrschulen!$C$2:$C$45,"Pforzheim",Fahrschulen!$Q$2:$Q$45,"Ja") -> 0 | C18: =COUNTIFS(Fahrschulen!$C$2:$C$45,"Enzkreis",Fahrschulen!$Q$2:$Q$45,"Ja") -> 0 | D18: =B18+C18 -> 0
A19: Tipps / Leads | B19: =SUMIFS(Fahrschulen!$R$2:$R$45,Fahrschulen!$C$2:$C$45,"Pforzheim") -> 0 | C19: =SUMIFS(Fahrschulen!$R$2:$R$45,Fahrschulen!$C$2:$C$45,"Enzkreis") -> 0 | D19: =B19+C19 -> 0
A20: Abschlüsse | B20: =SUMIFS(Fahrschulen!$S$2:$S$45,Fahrschulen!$C$2:$C$45,"Pforzheim") -> 0 | C20: =SUMIFS(Fahrschulen!$S$2:$S$45,Fahrschulen!$C$2:$C$45,"Enzkreis") -> 0 | D20: =B20+C20 -> 0
A21: Abschlussquote (Abschlüsse / Leads) | B21: =IFERROR(B20/B19,0) -> 0 | C21: =IFERROR(C20/C19,0) -> 0 | D21: =IFERROR(D20/D19,0) -> 0
A22: Provision gesamt (€) | B22: =SUMIFS(Fahrschulen!$U$2:$U$45,Fahrschulen!$C$2:$C$45,"Pforzheim") -> 0 | C22: =SUMIFS(Fahrschulen!$U$2:$U$45,Fahrschulen!$C$2:$C$45,"Enzkreis") -> 0 | D22: =B22+C22 -> 0
A23: Hinweise
A24: • Daten stammen aus Branchenverzeichnissen (Das Örtliche, golocal, 11880, Gelbe Seiten, cylex, city-map, clickclickdrive, fahrschulen24, YellowMap).
A25: • Adressen teils widersprüchlich/veraltet – vor dem Anschreiben „Daten geprüft“ auf Ja setzen.
A26: • Mögliche Doppelungen: Weiss / Veser + Weiss, Bernd / Patric Waidner, No Limit (Mühlacker + Knittlingen).
A27: • Provision nur als Tippgeber-Modell (nur Kontaktweitergabe, keine Beratung) – sonst §34d GewO. Vorher mit tecis-Compliance klären.

Sheet Fahrschulen
A1: Nr | B1: Fahrschule | C1: Gebiet | D1: Ort | E1: Adresse | F1: Telefon | G1: Website | H1: E-Mail | I1: Quelle | J1: Hinweis | K1: Daten geprüft | L1: Status | M1: Ansprechpartner | N1: Letzter Kontakt | O1: Nächster Schritt | P1: Termin Vortrag | Q1: Tippgeber-Vereinbarung | R1: Tipps / Leads | S1: Abschlüsse | T1: Notizen | U1: Provision (€) | V1: Interesse Flotte (Marvin)
A2: 1 | B2: Fahrschule Britsch | C2: Pforzheim | D2: Pforzheim-Nordstadt | E2: Christophallee 10 | F2: 07231 589797 | I2: Das Örtliche / golocal | K2: Nein | L2: Offen | Q2: Nein | R2: 0 | S2: 0 | U2: =S2*Übersicht!$G$4 -> 0 | V2: Offen
A3: 2 | B3: Fahrschule Veser + Weiss GmbH | C3: Pforzheim | D3: Pforzheim-Nordstadt | E3: Welschenäckerstr. 9, 75172 Pforzheim | F3: 07231 17889 | I3: Das Örtliche / golocal | J3: Schwerpunkt LKW & Bus | K3: Nein | L3: Offen | Q3: Nein | R3: 0 | S3: 0 | U3: =S3*Übersicht!$G$4 -> 0 | V3: Offen
A4: 3 | B4: Fahrschule Becht | C4: Pforzheim | D4: Pforzheim-Südweststadt | E4: Bleichstr. 46 | F4: 07231 22398 | I4: Das Örtliche / golocal | K4: Nein | L4: Offen | Q4: Nein | R4: 0 | S4: 0 | U4: =S4*Übersicht!$G$4 -> 0 | V4: Offen
A5: 4 | B5: Fahrschule Birr | C5: Pforzheim | D5: Pforzheim-Weststadt | E5: Westliche Karl-Friedrich-Str. 102 | F5: 0172 7203117 | I5: Das Örtliche / golocal | K5: Nein | L5: Offen | Q5: Nein | R5: 0 | S5: 0 | U5: =S5*Übersicht!$G$4 -> 0 | V5: Offen
A6: 5 | B6: Fahrschule Gisela GmbH | C6: Pforzheim | D6: Pforzheim-Südstadt | E6: Holzgartenstr. 30 | F6: 07231 601166 | I6: Das Örtliche / golocal | K6: Nein | L6: Offen | Q6: Nein | R6: 0 | S6: 0 | U6: =S6*Übersicht!$G$4 -> 0 | V6: Offen
A7: 6 | B7: Fahrschule Weiss GmbH | C7: Pforzheim | D7: Pforzheim-Innenstadt | E7: Zerrennerstr. 15 | F7: 07231 23310 | I7: Das Örtliche / golocal | J7: Evtl. verbunden mit Veser + Weiss – prüfen | K7: Nein | L7: Offen | Q7: Nein | R7: 0 | S7: 0 | U7: =S7*Übersicht!$G$4 -> 0 | V7: Offen
A8: 7 | B8: Fahrschule X | C8: Pforzheim | D8: Pforzheim-Brötzingen | E8: Westliche Karl-Friedrich-Str. 271 | F8: 0176 21506336 | I8: Das Örtliche / golocal | K8: Nein | L8: Offen | Q8: Nein | R8: 0 | S8: 0 | U8: =S8*Übersicht!$G$4 -> 0 | V8: Offen
A9: 8 | B9: Fahrschule Richard Kirschler | C9: Pforzheim | D9: Pforzheim-Innenstadt | E9: Zerrennerstr. 32 | F9: 0171 6544009 | I9: Das Örtliche / golocal | K9: Nein | L9: Offen | Q9: Nein | R9: 0 | S9: 0 | U9: =S9*Übersicht!$G$4 -> 0 | V9: Offen
A10: 9 | B10: Fahrschule Thomas Seewald | C10: Pforzheim | D10: Pforzheim-Südweststadt | E10: Jahnstr. 25 | F10: 07231 27731 | I10: Das Örtliche / golocal | K10: Nein | L10: Offen | Q10: Nein | R10: 0 | S10: 0 | U10: =S10*Übersicht!$G$4 -> 0 | V10: Offen
A11: 10 | B11: Fahrschule Schwarzer GbR | C11: Pforzheim | D11: Pforzheim-Südweststadt | E11: Bleichstr. 35 | F11: 07231 25204 | I11: Das Örtliche / cylex | K11: Nein | L11: Offen | Q11: Nein | R11: 0 | S11: 0 | U11: =S11*Übersicht!$G$4 -> 0 | V11: Offen
A12: 11 | B12: Fahrschule Manfred Klinger | C12: Pforzheim | D12: Pforzheim-Südweststadt | E12: Vogesenallee 8 | F12: 07231 789373 | I12: Das Örtliche / golocal | K12: Nein | L12: Offen | Q12: Nein | R12: 0 | S12: 0 | U12: =S12*Übersicht!$G$4 -> 0 | V12: Offen
A13: 12 | B13: Fahrschule T. Kunzmann | C13: Pforzheim | D13: Pforzheim-Nordstadt | E13: Christophallee 24 | F13: 07231 424963 | I13: Das Örtliche / golocal | K13: Nein | L13: Offen | Q13: Nein | R13: 0 | S13: 0 | U13: =S13*Übersicht!$G$4 -> 0 | V13: Offen
A14: 13 | B14: Fahrschule Frank Lieberwirth | C14: Pforzheim | D14: Pforzheim-Eutingen | E14: Meisenstr. 4 | F14: 07231 51228 | I14: Das Örtliche / golocal | K14: Nein | L14: Offen | Q14: Nein | R14: 0 | S14: 0 | U14: =S14*Übersicht!$G$4 -> 0 | V14: Offen
A15: 14 | B15: Fahrschule Jürgen Anthoni Mikol | C15: Pforzheim | D15: Pforzheim-Innenstadt | E15: Westliche Karl-Friedrich-Str. 214 | F15: 0170 8036954 | I15: Das Örtliche / golocal | K15: Nein | L15: Offen | Q15: Nein | R15: 0 | S15: 0 | U15: =S15*Übersicht!$G$4 -> 0 | V15: Offen
A16: 15 | B16: Die Autohaus Fahrschule (ahg) | C16: Pforzheim | D16: Pforzheim-Wilferdinger Höhe | E16: Karlsruher Str. 69 | F16: 07231 930878 | I16: Das Örtliche / golocal | J16: Alt. Tel. 07231 9308-20; auch Anhänger- & Auffrischungskurse | K16: Nein | L16: Offen | Q16: Nein | R16: 0 | S16: 0 | U16: =S16*Übersicht!$G$4 -> 0 | V16: Offen
A17: 16 | B17: Fahrschule Kästner | C17: Pforzheim | D17: Pforzheim | I17: genaumeinkurs.de | J17: Älteste Fahrschule Pforzheims (seit 1956) – Adresse/Telefon fehlen | K17: Nein | L17: Offen | Q17: Nein | R17: 0 | S17: 0 | U17: =S17*Übersicht!$G$4 -> 0 | V17: Offen
A18: 17 | B18: Fahrschule Fischer (Gerhard Fischer) | C18: Enzkreis | D18: Remchingen | E18: Wilferdinger Str. 7, 75196 Remchingen | F18: 07232 70909 | I18: cylex / 11880 | J18: Büro laut Eintrag Di + Do abends | K18: Nein | L18: Offen | Q18: Nein | R18: 0 | S18: 0 | U18: =S18*Übersicht!$G$4 -> 0 | V18: Offen
A19: 18 | B19: Fahrschule Six | C19: Enzkreis | D19: Remchingen-Wilferdingen | E19: Pforzheimer Str. 8, 75196 Remchingen | F19: 0177 6611723 | I19: 11880 | K19: Nein | L19: Offen | Q19: Nein | R19: 0 | S19: 0 | U19: =S19*Übersicht!$G$4 -> 0 | V19: Offen
A20: 19 | B20: Fahrschule Uwe Wallner | C20: Enzkreis | D20: Königsbach-Stein | E20: Walter-Rathenau-Str. 6, 75203 Königsbach-Stein | F20: 07232 9489 | I20: 11880 | K20: Nein | L20: Offen | Q20: Nein | R20: 0 | S20: 0 | U20: =S20*Übersicht!$G$4 -> 0 | V20: Offen
A21: 20 | B21: Christa Bohrer, Fahrlehrerin | C21: Enzkreis | D21: Mühlacker-Großglattbach | E21: Fronackerweg 30, 75417 Mühlacker | F21: 07042 93227 | I21: Branchenverzeichnis | J21: Eintrag evtl. veraltet | K21: Nein | L21: Offen | Q21: Nein | R21: 0 | S21: 0 | U21: =S21*Übersicht!$G$4 -> 0 | V21: Offen
A22: 21 | B22: Fahrschule No Limit | C22: Enzkreis | D22: Mühlacker / Knittlingen | E22: Bahnhofstr. 71, 75417 Mühlacker | G22: fahrschule-123.de | I22: fahrschule-123.de / clickclickdrive | J22: Auch in Knittlingen gelistet | K22: Nein | L22: Offen | Q22: Nein | R22: 0 | S22: 0 | U22: =S22*Übersicht!$G$4 -> 0 | V22: Offen
A23: 22 | B23: Tom Engel Fahrschule | C23: Enzkreis | D23: Mühlacker | E23: Bahnhofstr. 120, 75417 Mühlacker | I23: Gelbe Seiten | K23: Nein | L23: Offen | Q23: Nein | R23: 0 | S23: 0 | U23: =S23*Übersicht!$G$4 -> 0 | V23: Offen
A24: 23 | B24: Fahrschule Jim Engel | C24: Enzkreis | D24: Mühlacker / Niefern | E24: Filiale Niefern: Schloßstr. 13 | G24: fahrschule-jimengel.de | I24: Eigene Website | J24: Mehrere Filialen (Mühlacker, Niefern) | K24: Nein | L24: Offen | Q24: Nein | R24: 0 | S24: 0 | U24: =S24*Übersicht!$G$4 -> 0 | V24: Offen
A25: 24 | B25: TIP Fahrschule + Sportbootschule GmbH | C25: Enzkreis | D25: Niefern-Öschelbronn | I25: Lifestyle Cars Mobility | J25: Auch Bootsführerschein | K25: Nein | L25: Offen | Q25: Nein | R25: 0 | S25: 0 | U25: =S25*Übersicht!$G$4 -> 0 | V25: Offen
A26: 25 | B26: Fahrschule Alexander Fröhlich | C26: Enzkreis | D26: Knittlingen | E26: Stuttgarter Str. 7, Knittlingen | I26: clickclickdrive / 11880 | K26: Nein | L26: Offen | Q26: Nein | R26: 0 | S26: 0 | U26: =S26*Übersicht!$G$4 -> 0 | V26: Offen
A27: 26 | B27: Udo's Fahrschule | C27: Enzkreis | D27: Knittlingen | E27: Weißhoferstr. 65, Knittlingen | I27: city-map | K27: Nein | L27: Offen | Q27: Nein | R27: 0 | S27: 0 | U27: =S27*Übersicht!$G$4 -> 0 | V27: Offen
A28: 27 | B28: Fahrschule Jörg's | C28: Enzkreis | D28: Knittlingen | E28: Rote-Tor-Str. 4, Knittlingen | I28: city-map | K28: Nein | L28: Offen | Q28: Nein | R28: 0 | S28: 0 | U28: =S28*Übersicht!$G$4 -> 0 | V28: Offen
A29: 28 | B29: Fahrschule Hans Jaggy | C29: Enzkreis | D29: Maulbronn | E29: Hermann-Hesse-Str. 15, 75433 Maulbronn | I29: 11880 | K29: Nein | L29: Offen | Q29: Nein | R29: 0 | S29: 0 | U29: =S29*Übersicht!$G$4 -> 0 | V29: Offen
A30: 29 | B30: Academy Fahrschule SNH | C30: Enzkreis | D30: Ötisheim | E30: Maulbronner Str. 46, 75443 Ötisheim | I30: city-map / 11880 | K30: Nein | L30: Offen | Q30: Nein | R30: 0 | S30: 0 | U30: =S30*Übersicht!$G$4 -> 0 | V30: Offen
A31: 30 | B31: Fahrschule Jürgen Kölmel | C31: Enzkreis | D31: Wiernsheim | E31: Wurmberger Str. 3, Wiernsheim | I31: city-map / YellowMap | J31: Alt. Adresse: Mühlacker Str. 8 | K31: Nein | L31: Offen | Q31: Nein | R31: 0 | S31: 0 | U31: =S31*Übersicht!$G$4 -> 0 | V31: Offen
A32: 31 | B32: ASS Fahrerschulung Nenad Jilke | C32: Enzkreis | D32: Illingen | E32: Uhlandstr. 18, Illingen | I32: 11880 | K32: Nein | L32: Offen | Q32: Nein | R32: 0 | S32: 0 | U32: =S32*Übersicht!$G$4 -> 0 | V32: Offen
A33: 32 | B33: Stefan Kurbel, Fahrlehrer | C33: Enzkreis | D33: Illingen | E33: Silcherweg 6, Illingen | I33: 11880 | K33: Nein | L33: Offen | Q33: Nein | R33: 0 | S33: 0 | U33: =S33*Übersicht!$G$4 -> 0 | V33: Offen
A34: 33 | B34: Steffens Fahrschule | C34: Enzkreis | D34: Illingen | E34: Bahnhofstr. 15, Illingen | I34: 11880 | J34: Laut 11880 evtl. geschlossen | K34: Nein | L34: Offen | Q34: Nein | R34: 0 | S34: 0 | U34: =S34*Übersicht!$G$4 -> 0 | V34: Offen
A35: 34 | B35: Fahrschule Sasse | C35: Enzkreis | D35: Friolzheim | E35: Lerchenstr. 35, Friolzheim | I35: city-map | J35: Alt. Adresse: Lerchenstr. 50 | K35: Nein | L35: Offen | Q35: Nein | R35: 0 | S35: 0 | U35: =S35*Übersicht!$G$4 -> 0 | V35: Offen
A36: 35 | B36: Frank's Fahrschule | C36: Enzkreis | D36: Birkenfeld | E36: Marktplatz 4, 75217 Birkenfeld | I36: clickclickdrive | J36: Teils Marktplatz 5 angegeben | K36: Nein | L36: Offen | Q36: Nein | R36: 0 | S36: 0 | U36: =S36*Übersicht!$G$4 -> 0 | V36: Offen
A37: 36 | B37: Fahrschule Bernd Waidner | C37: Enzkreis | D37: Birkenfeld | I37: clickclickdrive | J37: Evtl. verbunden mit Patric Waidner – prüfen | K37: Nein | L37: Offen | Q37: Nein | R37: 0 | S37: 0 | U37: =S37*Übersicht!$G$4 -> 0 | V37: Offen
A38: 37 | B38: Fahrschule Patric Waidner | C38: Enzkreis | D38: Straubenhardt | E38: Hauptstr. 69, 75334 Straubenhardt | I38: YellowMap | K38: Nein | L38: Offen | Q38: Nein | R38: 0 | S38: 0 | U38: =S38*Übersicht!$G$4 -> 0 | V38: Offen
A39: 38 | B39: Fahrschule Klaus Jost | C39: Enzkreis | D39: Neuenbürg | E39: Klingstr. 2, 75305 Neuenbürg | I39: fahrschule-die-lizenz.de | K39: Nein | L39: Offen | Q39: Nein | R39: 0 | S39: 0 | U39: =S39*Übersicht!$G$4 -> 0 | V39: Offen
A40: 39 | B40: Rüdiger's Fahrschule | C40: Enzkreis | D40: Neuenbürg / Straubenhardt | E40: Ottenhäuser Str. 2, 75305 Neuenbürg | I40: fahrschulen24 / YellowMap | J40: Filiale: Neuenbürger Str. 47, 75334 Straubenhardt | K40: Nein | L40: Offen | Q40: Nein | R40: 0 | S40: 0 | U40: =S40*Übersicht!$G$4 -> 0 | V40: Offen
...

Sheet Legende
A1: Legende
A2: Gelbe Zellen | B2: Hier trägst du ein (Blatt „Fahrschulen“, Spalten H und K–T). Weiße Spalten = Recherche-Daten.
A3: Status | B3: Auswahlliste: Offen, Angeschrieben, Angerufen, Nachfassen, Termin vereinbart, Vortrag gehalten, Kooperation aktiv, Kein Interesse, Geschlossen / existiert nicht
A4: Daten geprüft | B4: Ja, sobald Adresse/Telefon/Inhaber telefonisch oder per Website bestätigt sind.
A5: Tippgeber-Vereinbarung | B5: Ja / Nein / In Prüfung
A6: Datumsfelder | B6: Format TT.MM.JJJJ
A7: Farben | B7: Grün = Kooperation aktiv · Blau = Termin vereinbart / Vortrag gehalten · Grau = Kein Interesse / geschlossen
A9: Beispielzeile (so ausfüllen)
A10: Status | B10: Termin vereinbart
A11: Ansprechpartner | B11: Herr Müller (Inhaber)
A12: Letzter Kontakt | B12: 03.11.2026
A13: Nächster Schritt | B13: Flyer + Tippgeber-Vereinbarung mitbringen
A14: Termin Vortrag | B14: 19.11.2026
A15: Tippgeber-Vereinbarung | B15: In Prüfung
A16: Tipps / Leads | B16: 0
A17: Notizen | B17: Theorieunterricht Di/Do 18 Uhr, ca. 15 Schüler
A18: Provision | B18: Spalte U rechnet automatisch: Abschlüsse × 60 € (Wert in Übersicht!G4). Nur Abschlüsse eintragen, die aus Empfehlungen der Fahrschule entstanden sind.
A19: Interesse Flotte (Marvin) | B19: Offen / Ja / Nein / An Marvin übergeben – ob die Fahrschule ihre eigenen Fahrschulautos von Marvin Mönig (Gewerbefahrzeuge) vergleichen lassen möchte.
